#VRML_SIM R2019a utf8
WorldInfo {
}
Viewpoint {
  orientation -0.2696054281025459 -0.9423141976419913 -0.19838564983378437 1.3259499238706225
  position -0.2641329133870507 1.830982044577581 1.0387027590129654
}
TexturedBackground {
}
TexturedBackgroundLight {
}
Floor {
}
Solid {
  translation 0.01 -0.019318516529918055 -0.005176380886612051
  rotation 1 0 0 0.2617993870000007
  children [
    DEF BASE Group {
      children [
        Transform {
          translation -0.015529144882963006 0.465 -0.01
          rotation 0.7040625396160338 0.09269160524965252 -0.7040626439640607 0.3697100193516104
          children [
            Shape {
              appearance DEF COLOR_1 PBRAppearance {
                baseColor 0.4451209277485313 0.2500038147554742 0.7499961852445258
                roughness 1
                metalness 0
              }
              geometry DEF CYL1_BASE Cylinder {
                height 1
                radius 0.04
              }
            }
          ]
        }
        Transform {
          translation 0.24 0.465 -0.01
          rotation 0.7040625922383151 -0.09269159843982881 0.7040625922383135 0.36970999234435237
          children [
            Shape {
              appearance USE COLOR_1
              geometry USE CYL1_BASE
            }
          ]
        }
        Transform {
          translation 0.23625184091454932 0.589413428023647 0.4398686009098698
          rotation -0.9456067617707381 0.12449149153825788 0.30054903198652694 0.8257271908053714
          children [
            Shape {
              appearance USE COLOR_1
              geometry USE CYL1_BASE
            }
          ]
        }
        Transform {
          translation -0.013753706390320128 0.589 0.44
          rotation -0.9456067520381765 -0.12449149948228833 -0.3005490593172138 0.8257271784334304
          children [
            Transform {
              children [
                Shape {
                  appearance USE COLOR_1
                  geometry USE CYL1_BASE
                }
              ]
            }
          ]
        }
        Transform {
          translation 0.26 0.47286331418473626 0.21749423450215832
          rotation -1 0 0 4.974188391359173
          children [
            Shape {
              appearance USE COLOR_1
              geometry DEF CYL_B2 Cylinder {
                height 0.55
                radius 0.03
              }
            }
          ]
        }
        Transform {
          translation -0.039999999999999994 0.4657317759947837 0.23523991878172407
          rotation 1 0 0 4.450589579
          children [
            Shape {
              appearance USE COLOR_1
              geometry USE CYL_B2
            }
          ]
        }
        Transform {
          translation 0.10999999999999999 0.9695791681186925 0.10255103883921242
          rotation 1 0 0 1.3089969349999997
          children [
            Shape {
              appearance USE COLOR_1
              geometry Box {
                size 0.6 0.6 0.05
              }
            }
          ]
        }
      ]
    }
    DEF CIL_BS_HEL Transform {
      translation 0.11 1.2303791414074259 0.03266754336529336
      rotation 1 0 0 6.021385901
      children [
        Shape {
          appearance DEF COLOR2 PBRAppearance {
            baseColor 0.06926070038910506 0.9033340962844282 0.5981841763942931
            roughness 1
            metalness 0
          }
          geometry Cylinder {
            height 0.5
            radius 0.05
          }
        }
      ]
    }
    DEF HELIX_JOINT Transform {
      translation 0.10999999999999999 1.616749470020171 -0.0708600817773696
      rotation 1 0 0 6.021385901
      children [
        Shape {
          appearance USE COLOR2
          geometry Box {
            size 0.4 0.30000000000000004 0.7
          }
        }
        HingeJoint {
          jointParameters HingeJointParameters {
            axis 0 0 1
            anchor 0 0 -0.37
          }
          endPoint Solid {
            translation 0 -0.5000000000000002 0.37
            rotation 0 0 1 0
            children [
              Group {
                children [
                  DEF STICK Group {
                    children [
                      Transform {
                        translation 0 0.5700000000000001 -0.7500000000000001
                        children [
                          Shape {
                            appearance USE COLOR2
                            geometry DEF HELICE Cylinder {
                              height 0.6
                              radius 0.02
                            }
                          }
                        ]
                      }
                      Transform {
                        translation 0 0.7999999999999999 -0.7500000000000002
                        children [
                          Shape {
                            appearance USE COLOR2
                            geometry DEF B-HELIX Box {
                              size 0.05 0.2 0.05
                            }
                          }
                        ]
                      }
                      Transform {
                        translation 0 0.20000000000000004 -0.75
                        children [
                          Shape {
                            appearance USE COLOR2
                            geometry USE B-HELIX
                          }
                        ]
                      }
                      Transform {
                        translation 0.4800000024933465 0.5199999976984503 0
                        rotation 0 0 1 1.5707963220000003
                        children [
                          DEF STICK Group {
                            children [
                              Transform {
                                translation 0 0.5700000000000001 -0.7500000000000001
                                children [
                                  Shape {
                                    appearance USE COLOR2
                                    geometry DEF HELICE Cylinder {
                                      height 0.6
                                      radius 0.02
                                    }
                                  }
                                ]
                              }
                              Transform {
                                translation 0 0.7999999999999999 -0.7500000000000002
                                children [
                                  Shape {
                                    appearance USE COLOR2
                                    geometry DEF B-HELIX Box {
                                      size 0.05 0.2 0.05
                                    }
                                  }
                                ]
                              }
                              Transform {
                                translation 0 0.20000000000000004 -0.75
                                children [
                                  Shape {
                                    appearance USE COLOR2
                                    geometry USE B-HELIX
                                  }
                                ]
                              }
                            ]
                          }
                        ]
                      }
                      Transform {
                        translation -0.33941127561771217 0.1896342064314547 1.4224732503009818e-16
                        rotation 0 0 1 5.497787127
                        children [
                          USE STICK
                        ]
                      }
                      Transform {
                        translation 0.3394112519858994 0.1654920642979566 0.003000000000000034
                        rotation 0 0 1 0.7853981610000004
                        children [
                          USE STICK
                        ]
                      }
                    ]
                  }
                ]
              }
            ]
            physics Physics {
            }
          }
        }
      ]
    }
    Transform {
      translation 0.10999999999999999 1.79221274201389 0.5202129335454423
      rotation -1 0 0 1.832595747359173
      children [
        HingeJoint {
          jointParameters HingeJointParameters {
            axis 0 0 1
            anchor 0 0.27999999999999997 0
            minStop -1.5708
            maxStop 1.5708
          }
          endPoint Solid {
            translation 0 3.8163916471489756e-17 0
            rotation 0 0 1 0
            children [
              Group {
                children [
                  Transform {
                    children [
                      Shape {
                        appearance USE COLOR2
                        geometry USE CYL_B2
                      }
                    ]
                  }
                  Transform {
                    translation 0 -0.30000000000000004 0
                    children [
                      Shape {
                        appearance USE COLOR2
                        geometry Box {
                          size 0.060000000000000005 0.30000000000000004 0.15
                        }
                      }
                    ]
                  }
                ]
              }
            ]
            name "solid(1)"
            physics Physics {
            }
          }
        }
      ]
    }
  ]
}
